2019-03-13 14:00:56,127 [Thread-2:1916] [django.request:228] [log:log_response] [WARNING]- Bad Request: /open_now/39347/
2019-03-13 14:02:25,078 [Thread-2:2884] [django.request:228] [log:log_response] [WARNING]- Bad Request: /open_now/39347/
2019-03-13 14:03:30,801 [Thread-2:3304] [django.request:228] [log:log_response] [WARNING]- Bad Request: /open_now/39347/
2019-03-13 14:04:10,780 [Thread-2:7256] [django.request:228] [log:log_response] [WARNING]- Bad Request: /open_now/39347/
2019-03-13 14:04:47,071 [Thread-2:7256] [django.request:228] [log:log_response] [WARNING]- Bad Request: /open_now/39347/
2019-03-14 10:54:45,057 [Thread-3:6368] [django.request:228] [log:log_response] [WARNING]- Forbidden: /welfares/
2019-03-15 11:07:45,463 [Thread-3:6248] [django.request:228] [log:log_response] [WARNING]- Forbidden: /welfares/
2019-03-18 10:37:56,162 [Thread-8:4788] [django.request:228] [log:log_response] [WARNING]- Forbidden: /welfares/
2019-03-19 10:39:09,160 [Thread-8:13332] [django.request:228] [log:log_response] [WARNING]- Forbidden: /welfares/
2019-03-19 14:50:19,156 [Thread-2:2996] [django.request:228] [log:log_response] [ERROR]- Internal Server Error: /user_permissions/114/
Traceback (most recent call last):
  File "E:\workspace\venv\django_ro_venv\lib\site-packages\django\core\handlers\exception.py", line 34, in inner
    response = get_response(request)
  File "E:\workspace\venv\django_ro_venv\lib\site-packages\django\core\handlers\base.py", line 126, in _get_response
    response = self.process_exception_by_middleware(e, request)
  File "E:\workspace\venv\django_ro_venv\lib\site-packages\django\core\handlers\base.py", line 124, in _get_response
    response = wrapped_callback(request, *callback_args, **callback_kwargs)
  File "E:\workspace\venv\django_ro_venv\lib\site-packages\django\views\decorators\csrf.py", line 54, in wrapped_view
    return view_func(*args, **kwargs)
  File "E:\workspace\venv\django_ro_venv\lib\site-packages\django\views\generic\base.py", line 68, in view
    return self.dispatch(request, *args, **kwargs)
  File "E:\workspace\venv\django_ro_venv\lib\site-packages\rest_framework\views.py", line 495, in dispatch
    response = self.handle_exception(exc)
  File "E:\workspace\venv\django_ro_venv\lib\site-packages\rest_framework\views.py", line 455, in handle_exception
    self.raise_uncaught_exception(exc)
  File "E:\workspace\venv\django_ro_venv\lib\site-packages\rest_framework\views.py", line 492, in dispatch
    response = handler(request, *args, **kwargs)
  File "E:\workspace\venv\django_ro_venv\lib\site-packages\rest_framework\decorators.py", line 54, in handler
    return func(*args, **kwargs)
  File "E:\workspace\project\django_ro\ro_operations\views.py", line 119, in user_permission
    for k, v in settings.USER_PERMISSION:
TypeError: 'int' object is not iterable
2019-03-19 14:50:21,553 [Thread-2:2996] [django.request:228] [log:log_response] [ERROR]- Internal Server Error: /user_permissions/114/
Traceback (most recent call last):
  File "E:\workspace\venv\django_ro_venv\lib\site-packages\django\core\handlers\exception.py", line 34, in inner
    response = get_response(request)
  File "E:\workspace\venv\django_ro_venv\lib\site-packages\django\core\handlers\base.py", line 126, in _get_response
    response = self.process_exception_by_middleware(e, request)
  File "E:\workspace\venv\django_ro_venv\lib\site-packages\django\core\handlers\base.py", line 124, in _get_response
    response = wrapped_callback(request, *callback_args, **callback_kwargs)
  File "E:\workspace\venv\django_ro_venv\lib\site-packages\django\views\decorators\csrf.py", line 54, in wrapped_view
    return view_func(*args, **kwargs)
  File "E:\workspace\venv\django_ro_venv\lib\site-packages\django\views\generic\base.py", line 68, in view
    return self.dispatch(request, *args, **kwargs)
  File "E:\workspace\venv\django_ro_venv\lib\site-packages\rest_framework\views.py", line 495, in dispatch
    response = self.handle_exception(exc)
  File "E:\workspace\venv\django_ro_venv\lib\site-packages\rest_framework\views.py", line 455, in handle_exception
    self.raise_uncaught_exception(exc)
  File "E:\workspace\venv\django_ro_venv\lib\site-packages\rest_framework\views.py", line 492, in dispatch
    response = handler(request, *args, **kwargs)
  File "E:\workspace\venv\django_ro_venv\lib\site-packages\rest_framework\decorators.py", line 54, in handler
    return func(*args, **kwargs)
  File "E:\workspace\project\django_ro\ro_operations\views.py", line 119, in user_permission
    for k, v in settings.USER_PERMISSION:
TypeError: 'int' object is not iterable
2019-03-19 14:50:26,462 [Thread-2:2996] [django.request:228] [log:log_response] [ERROR]- Internal Server Error: /user_permissions/114/
Traceback (most recent call last):
  File "E:\workspace\venv\django_ro_venv\lib\site-packages\django\core\handlers\exception.py", line 34, in inner
    response = get_response(request)
  File "E:\workspace\venv\django_ro_venv\lib\site-packages\django\core\handlers\base.py", line 126, in _get_response
    response = self.process_exception_by_middleware(e, request)
  File "E:\workspace\venv\django_ro_venv\lib\site-packages\django\core\handlers\base.py", line 124, in _get_response
    response = wrapped_callback(request, *callback_args, **callback_kwargs)
  File "E:\workspace\venv\django_ro_venv\lib\site-packages\django\views\decorators\csrf.py", line 54, in wrapped_view
    return view_func(*args, **kwargs)
  File "E:\workspace\venv\django_ro_venv\lib\site-packages\django\views\generic\base.py", line 68, in view
    return self.dispatch(request, *args, **kwargs)
  File "E:\workspace\venv\django_ro_venv\lib\site-packages\rest_framework\views.py", line 495, in dispatch
    response = self.handle_exception(exc)
  File "E:\workspace\venv\django_ro_venv\lib\site-packages\rest_framework\views.py", line 455, in handle_exception
    self.raise_uncaught_exception(exc)
  File "E:\workspace\venv\django_ro_venv\lib\site-packages\rest_framework\views.py", line 492, in dispatch
    response = handler(request, *args, **kwargs)
  File "E:\workspace\venv\django_ro_venv\lib\site-packages\rest_framework\decorators.py", line 54, in handler
    return func(*args, **kwargs)
  File "E:\workspace\project\django_ro\ro_operations\views.py", line 119, in user_permission
    for k, v in settings.USER_PERMISSION:
TypeError: 'int' object is not iterable
2019-03-19 14:51:13,779 [Thread-3:6548] [django.request:228] [log:log_response] [ERROR]- Internal Server Error: /user_permissions/114/
Traceback (most recent call last):
  File "E:\workspace\venv\django_ro_venv\lib\site-packages\django\core\handlers\exception.py", line 34, in inner
    response = get_response(request)
  File "E:\workspace\venv\django_ro_venv\lib\site-packages\django\core\handlers\base.py", line 126, in _get_response
    response = self.process_exception_by_middleware(e, request)
  File "E:\workspace\venv\django_ro_venv\lib\site-packages\django\core\handlers\base.py", line 124, in _get_response
    response = wrapped_callback(request, *callback_args, **callback_kwargs)
  File "E:\workspace\venv\django_ro_venv\lib\site-packages\django\views\decorators\csrf.py", line 54, in wrapped_view
    return view_func(*args, **kwargs)
  File "E:\workspace\venv\django_ro_venv\lib\site-packages\django\views\generic\base.py", line 68, in view
    return self.dispatch(request, *args, **kwargs)
  File "E:\workspace\venv\django_ro_venv\lib\site-packages\rest_framework\views.py", line 495, in dispatch
    response = self.handle_exception(exc)
  File "E:\workspace\venv\django_ro_venv\lib\site-packages\rest_framework\views.py", line 455, in handle_exception
    self.raise_uncaught_exception(exc)
  File "E:\workspace\venv\django_ro_venv\lib\site-packages\rest_framework\views.py", line 492, in dispatch
    response = handler(request, *args, **kwargs)
  File "E:\workspace\venv\django_ro_venv\lib\site-packages\rest_framework\decorators.py", line 54, in handler
    return func(*args, **kwargs)
  File "E:\workspace\project\django_ro\ro_operations\views.py", line 119, in user_permission
    for k, v in settings.USER_PERMISSION:
TypeError: 'int' object is not iterable
2019-03-19 14:51:15,976 [Thread-4:12912] [django.request:228] [log:log_response] [ERROR]- Internal Server Error: /user_permissions/114/
Traceback (most recent call last):
  File "E:\workspace\venv\django_ro_venv\lib\site-packages\django\core\handlers\exception.py", line 34, in inner
    response = get_response(request)
  File "E:\workspace\venv\django_ro_venv\lib\site-packages\django\core\handlers\base.py", line 126, in _get_response
    response = self.process_exception_by_middleware(e, request)
  File "E:\workspace\venv\django_ro_venv\lib\site-packages\django\core\handlers\base.py", line 124, in _get_response
    response = wrapped_callback(request, *callback_args, **callback_kwargs)
  File "E:\workspace\venv\django_ro_venv\lib\site-packages\django\views\decorators\csrf.py", line 54, in wrapped_view
    return view_func(*args, **kwargs)
  File "E:\workspace\venv\django_ro_venv\lib\site-packages\django\views\generic\base.py", line 68, in view
    return self.dispatch(request, *args, **kwargs)
  File "E:\workspace\venv\django_ro_venv\lib\site-packages\rest_framework\views.py", line 495, in dispatch
    response = self.handle_exception(exc)
  File "E:\workspace\venv\django_ro_venv\lib\site-packages\rest_framework\views.py", line 455, in handle_exception
    self.raise_uncaught_exception(exc)
  File "E:\workspace\venv\django_ro_venv\lib\site-packages\rest_framework\views.py", line 492, in dispatch
    response = handler(request, *args, **kwargs)
  File "E:\workspace\venv\django_ro_venv\lib\site-packages\rest_framework\decorators.py", line 54, in handler
    return func(*args, **kwargs)
  File "E:\workspace\project\django_ro\ro_operations\views.py", line 119, in user_permission
    for k, v in settings.USER_PERMISSION:
TypeError: 'int' object is not iterable
2019-03-19 14:52:18,821 [Thread-4:12912] [django.request:228] [log:log_response] [ERROR]- Internal Server Error: /user_permissions/114/
Traceback (most recent call last):
  File "E:\workspace\venv\django_ro_venv\lib\site-packages\django\core\handlers\exception.py", line 34, in inner
    response = get_response(request)
  File "E:\workspace\venv\django_ro_venv\lib\site-packages\django\core\handlers\base.py", line 126, in _get_response
    response = self.process_exception_by_middleware(e, request)
  File "E:\workspace\venv\django_ro_venv\lib\site-packages\django\core\handlers\base.py", line 124, in _get_response
    response = wrapped_callback(request, *callback_args, **callback_kwargs)
  File "E:\workspace\venv\django_ro_venv\lib\site-packages\django\views\decorators\csrf.py", line 54, in wrapped_view
    return view_func(*args, **kwargs)
  File "E:\workspace\venv\django_ro_venv\lib\site-packages\django\views\generic\base.py", line 68, in view
    return self.dispatch(request, *args, **kwargs)
  File "E:\workspace\venv\django_ro_venv\lib\site-packages\rest_framework\views.py", line 495, in dispatch
    response = self.handle_exception(exc)
  File "E:\workspace\venv\django_ro_venv\lib\site-packages\rest_framework\views.py", line 455, in handle_exception
    self.raise_uncaught_exception(exc)
  File "E:\workspace\venv\django_ro_venv\lib\site-packages\rest_framework\views.py", line 492, in dispatch
    response = handler(request, *args, **kwargs)
  File "E:\workspace\venv\django_ro_venv\lib\site-packages\rest_framework\decorators.py", line 54, in handler
    return func(*args, **kwargs)
  File "E:\workspace\project\django_ro\ro_operations\views.py", line 119, in user_permission
    for k, v in settings.USER_PERMISSION:
TypeError: 'int' object is not iterable
