2019-02-22 13:45:06,009 [Thread-2:11284] [django.request:228] [log:log_response] [WARNING]- Forbidden: /server_managements/
2019-02-22 13:45:07,441 [Thread-2:11284] [django.request:228] [log:log_response] [WARNING]- Forbidden: /server_managements/
2019-02-22 13:51:00,277 [Thread-4:14480] [django.request:228] [log:log_response] [WARNING]- Forbidden: /server_managements/
2019-02-22 13:51:01,389 [Thread-4:14480] [django.request:228] [log:log_response] [WARNING]- Forbidden: /server_managements/
2019-02-22 13:55:52,221 [Thread-2:12212] [django.request:228] [log:log_response] [ERROR]- Internal Server Error: /server_managements/
Traceback (most recent call last):
  File "E:\workspace\venv\django_ro_venv\lib\site-packages\rest_framework\fields.py", line 454, in get_attribute
    return get_attribute(instance, self.source_attrs)
  File "E:\workspace\venv\django_ro_venv\lib\site-packages\rest_framework\fields.py", line 100, in get_attribute
    instance = instance[attr]
KeyError: 'max_users'

During handling of the above exception, another exception occurred:

Traceback (most recent call last):
  File "E:\workspace\venv\django_ro_venv\lib\site-packages\django\core\handlers\exception.py", line 34, in inner
    response = get_response(request)
  File "E:\workspace\venv\django_ro_venv\lib\site-packages\django\core\handlers\base.py", line 126, in _get_response
    response = self.process_exception_by_middleware(e, request)
  File "E:\workspace\venv\django_ro_venv\lib\site-packages\django\core\handlers\base.py", line 124, in _get_response
    response = wrapped_callback(request, *callback_args, **callback_kwargs)
  File "E:\workspace\venv\django_ro_venv\lib\site-packages\django\views\decorators\csrf.py", line 54, in wrapped_view
    return view_func(*args, **kwargs)
  File "E:\workspace\venv\django_ro_venv\lib\site-packages\django\views\generic\base.py", line 68, in view
    return self.dispatch(request, *args, **kwargs)
  File "E:\workspace\venv\django_ro_venv\lib\site-packages\rest_framework\views.py", line 495, in dispatch
    response = self.handle_exception(exc)
  File "E:\workspace\venv\django_ro_venv\lib\site-packages\rest_framework\views.py", line 455, in handle_exception
    self.raise_uncaught_exception(exc)
  File "E:\workspace\venv\django_ro_venv\lib\site-packages\rest_framework\views.py", line 492, in dispatch
    response = handler(request, *args, **kwargs)
  File "E:\workspace\project\django_ro\ro_operations\views.py", line 158, in get
    return Response(serializer.data)
  File "E:\workspace\venv\django_ro_venv\lib\site-packages\rest_framework\serializers.py", line 768, in data
    ret = super(ListSerializer, self).data
  File "E:\workspace\venv\django_ro_venv\lib\site-packages\rest_framework\serializers.py", line 262, in data
    self._data = self.to_representation(self.instance)
  File "E:\workspace\venv\django_ro_venv\lib\site-packages\rest_framework\serializers.py", line 686, in to_representation
    self.child.to_representation(item) for item in iterable
  File "E:\workspace\venv\django_ro_venv\lib\site-packages\rest_framework\serializers.py", line 686, in <listcomp>
    self.child.to_representation(item) for item in iterable
  File "E:\workspace\venv\django_ro_venv\lib\site-packages\rest_framework\serializers.py", line 517, in to_representation
    attribute = field.get_attribute(instance)
  File "E:\workspace\venv\django_ro_venv\lib\site-packages\rest_framework\fields.py", line 475, in get_attribute
    raise type(exc)(msg)
KeyError: "Got KeyError when attempting to get a value for field `max_users` on serializer `ServerManagementSerializer`.\nThe serializer field might be named incorrectly and not match any attribute or key on the `dict` instance.\nOriginal exception text was: 'max_users'."
2019-02-22 13:55:56,096 [Thread-2:12212] [django.request:228] [log:log_response] [ERROR]- Internal Server Error: /server_managements/
Traceback (most recent call last):
  File "E:\workspace\venv\django_ro_venv\lib\site-packages\rest_framework\fields.py", line 454, in get_attribute
    return get_attribute(instance, self.source_attrs)
  File "E:\workspace\venv\django_ro_venv\lib\site-packages\rest_framework\fields.py", line 100, in get_attribute
    instance = instance[attr]
KeyError: 'max_users'

During handling of the above exception, another exception occurred:

Traceback (most recent call last):
  File "E:\workspace\venv\django_ro_venv\lib\site-packages\django\core\handlers\exception.py", line 34, in inner
    response = get_response(request)
  File "E:\workspace\venv\django_ro_venv\lib\site-packages\django\core\handlers\base.py", line 126, in _get_response
    response = self.process_exception_by_middleware(e, request)
  File "E:\workspace\venv\django_ro_venv\lib\site-packages\django\core\handlers\base.py", line 124, in _get_response
    response = wrapped_callback(request, *callback_args, **callback_kwargs)
  File "E:\workspace\venv\django_ro_venv\lib\site-packages\django\views\decorators\csrf.py", line 54, in wrapped_view
    return view_func(*args, **kwargs)
  File "E:\workspace\venv\django_ro_venv\lib\site-packages\django\views\generic\base.py", line 68, in view
    return self.dispatch(request, *args, **kwargs)
  File "E:\workspace\venv\django_ro_venv\lib\site-packages\rest_framework\views.py", line 495, in dispatch
    response = self.handle_exception(exc)
  File "E:\workspace\venv\django_ro_venv\lib\site-packages\rest_framework\views.py", line 455, in handle_exception
    self.raise_uncaught_exception(exc)
  File "E:\workspace\venv\django_ro_venv\lib\site-packages\rest_framework\views.py", line 492, in dispatch
    response = handler(request, *args, **kwargs)
  File "E:\workspace\project\django_ro\ro_operations\views.py", line 158, in get
    return Response(serializer.data)
  File "E:\workspace\venv\django_ro_venv\lib\site-packages\rest_framework\serializers.py", line 768, in data
    ret = super(ListSerializer, self).data
  File "E:\workspace\venv\django_ro_venv\lib\site-packages\rest_framework\serializers.py", line 262, in data
    self._data = self.to_representation(self.instance)
  File "E:\workspace\venv\django_ro_venv\lib\site-packages\rest_framework\serializers.py", line 686, in to_representation
    self.child.to_representation(item) for item in iterable
  File "E:\workspace\venv\django_ro_venv\lib\site-packages\rest_framework\serializers.py", line 686, in <listcomp>
    self.child.to_representation(item) for item in iterable
  File "E:\workspace\venv\django_ro_venv\lib\site-packages\rest_framework\serializers.py", line 517, in to_representation
    attribute = field.get_attribute(instance)
  File "E:\workspace\venv\django_ro_venv\lib\site-packages\rest_framework\fields.py", line 475, in get_attribute
    raise type(exc)(msg)
KeyError: "Got KeyError when attempting to get a value for field `max_users` on serializer `ServerManagementSerializer`.\nThe serializer field might be named incorrectly and not match any attribute or key on the `dict` instance.\nOriginal exception text was: 'max_users'."
2019-02-22 14:04:01,814 [Thread-2:6972] [django.request:228] [log:log_response] [ERROR]- Internal Server Error: /server_managements/
Traceback (most recent call last):
  File "E:\workspace\venv\django_ro_venv\lib\site-packages\rest_framework\fields.py", line 454, in get_attribute
    return get_attribute(instance, self.source_attrs)
  File "E:\workspace\venv\django_ro_venv\lib\site-packages\rest_framework\fields.py", line 100, in get_attribute
    instance = instance[attr]
KeyError: 'max_users'

During handling of the above exception, another exception occurred:

Traceback (most recent call last):
  File "E:\workspace\venv\django_ro_venv\lib\site-packages\django\core\handlers\exception.py", line 34, in inner
    response = get_response(request)
  File "E:\workspace\venv\django_ro_venv\lib\site-packages\django\core\handlers\base.py", line 126, in _get_response
    response = self.process_exception_by_middleware(e, request)
  File "E:\workspace\venv\django_ro_venv\lib\site-packages\django\core\handlers\base.py", line 124, in _get_response
    response = wrapped_callback(request, *callback_args, **callback_kwargs)
  File "E:\workspace\venv\django_ro_venv\lib\site-packages\django\views\decorators\csrf.py", line 54, in wrapped_view
    return view_func(*args, **kwargs)
  File "E:\workspace\venv\django_ro_venv\lib\site-packages\django\views\generic\base.py", line 68, in view
    return self.dispatch(request, *args, **kwargs)
  File "E:\workspace\venv\django_ro_venv\lib\site-packages\rest_framework\views.py", line 495, in dispatch
    response = self.handle_exception(exc)
  File "E:\workspace\venv\django_ro_venv\lib\site-packages\rest_framework\views.py", line 455, in handle_exception
    self.raise_uncaught_exception(exc)
  File "E:\workspace\venv\django_ro_venv\lib\site-packages\rest_framework\views.py", line 492, in dispatch
    response = handler(request, *args, **kwargs)
  File "E:\workspace\project\django_ro\ro_operations\views.py", line 158, in get
    return Response(serializer.data)
  File "E:\workspace\venv\django_ro_venv\lib\site-packages\rest_framework\serializers.py", line 768, in data
    ret = super(ListSerializer, self).data
  File "E:\workspace\venv\django_ro_venv\lib\site-packages\rest_framework\serializers.py", line 262, in data
    self._data = self.to_representation(self.instance)
  File "E:\workspace\venv\django_ro_venv\lib\site-packages\rest_framework\serializers.py", line 686, in to_representation
    self.child.to_representation(item) for item in iterable
  File "E:\workspace\venv\django_ro_venv\lib\site-packages\rest_framework\serializers.py", line 686, in <listcomp>
    self.child.to_representation(item) for item in iterable
  File "E:\workspace\venv\django_ro_venv\lib\site-packages\rest_framework\serializers.py", line 517, in to_representation
    attribute = field.get_attribute(instance)
  File "E:\workspace\venv\django_ro_venv\lib\site-packages\rest_framework\fields.py", line 475, in get_attribute
    raise type(exc)(msg)
KeyError: "Got KeyError when attempting to get a value for field `max_users` on serializer `ServerManagementSerializer`.\nThe serializer field might be named incorrectly and not match any attribute or key on the `dict` instance.\nOriginal exception text was: 'max_users'."
2019-02-22 14:04:52,661 [Thread-2:9464] [django.request:228] [log:log_response] [ERROR]- Internal Server Error: /server_managements/
Traceback (most recent call last):
  File "E:\workspace\venv\django_ro_venv\lib\site-packages\rest_framework\fields.py", line 454, in get_attribute
    return get_attribute(instance, self.source_attrs)
  File "E:\workspace\venv\django_ro_venv\lib\site-packages\rest_framework\fields.py", line 100, in get_attribute
    instance = instance[attr]
KeyError: 'max_users'

During handling of the above exception, another exception occurred:

Traceback (most recent call last):
  File "E:\workspace\venv\django_ro_venv\lib\site-packages\django\core\handlers\exception.py", line 34, in inner
    response = get_response(request)
  File "E:\workspace\venv\django_ro_venv\lib\site-packages\django\core\handlers\base.py", line 126, in _get_response
    response = self.process_exception_by_middleware(e, request)
  File "E:\workspace\venv\django_ro_venv\lib\site-packages\django\core\handlers\base.py", line 124, in _get_response
    response = wrapped_callback(request, *callback_args, **callback_kwargs)
  File "E:\workspace\venv\django_ro_venv\lib\site-packages\django\views\decorators\csrf.py", line 54, in wrapped_view
    return view_func(*args, **kwargs)
  File "E:\workspace\venv\django_ro_venv\lib\site-packages\django\views\generic\base.py", line 68, in view
    return self.dispatch(request, *args, **kwargs)
  File "E:\workspace\venv\django_ro_venv\lib\site-packages\rest_framework\views.py", line 495, in dispatch
    response = self.handle_exception(exc)
  File "E:\workspace\venv\django_ro_venv\lib\site-packages\rest_framework\views.py", line 455, in handle_exception
    self.raise_uncaught_exception(exc)
  File "E:\workspace\venv\django_ro_venv\lib\site-packages\rest_framework\views.py", line 492, in dispatch
    response = handler(request, *args, **kwargs)
  File "E:\workspace\project\django_ro\ro_operations\views.py", line 159, in get
    return Response(serializer.data)
  File "E:\workspace\venv\django_ro_venv\lib\site-packages\rest_framework\serializers.py", line 768, in data
    ret = super(ListSerializer, self).data
  File "E:\workspace\venv\django_ro_venv\lib\site-packages\rest_framework\serializers.py", line 262, in data
    self._data = self.to_representation(self.instance)
  File "E:\workspace\venv\django_ro_venv\lib\site-packages\rest_framework\serializers.py", line 686, in to_representation
    self.child.to_representation(item) for item in iterable
  File "E:\workspace\venv\django_ro_venv\lib\site-packages\rest_framework\serializers.py", line 686, in <listcomp>
    self.child.to_representation(item) for item in iterable
  File "E:\workspace\venv\django_ro_venv\lib\site-packages\rest_framework\serializers.py", line 517, in to_representation
    attribute = field.get_attribute(instance)
  File "E:\workspace\venv\django_ro_venv\lib\site-packages\rest_framework\fields.py", line 475, in get_attribute
    raise type(exc)(msg)
KeyError: "Got KeyError when attempting to get a value for field `max_users` on serializer `ServerManagementSerializer`.\nThe serializer field might be named incorrectly and not match any attribute or key on the `dict` instance.\nOriginal exception text was: 'max_users'."
2019-02-23 14:57:19,253 [Thread-2:3540] [django.request:228] [log:log_response] [WARNING]- Forbidden: /welfares/
2019-02-23 15:19:46,118 [Thread-2:16880] [django.request:228] [log:log_response] [WARNING]- Not Found: /server_managements/app_channels
2019-02-23 15:57:22,381 [Thread-2:2236] [django.request:228] [log:log_response] [ERROR]- Internal Server Error: /app_server_channels/
Traceback (most recent call last):
  File "E:\workspace\venv\django_ro_venv\lib\site-packages\django\core\handlers\exception.py", line 34, in inner
    response = get_response(request)
  File "E:\workspace\venv\django_ro_venv\lib\site-packages\django\core\handlers\base.py", line 126, in _get_response
    response = self.process_exception_by_middleware(e, request)
  File "E:\workspace\venv\django_ro_venv\lib\site-packages\django\core\handlers\base.py", line 124, in _get_response
    response = wrapped_callback(request, *callback_args, **callback_kwargs)
  File "E:\workspace\venv\django_ro_venv\lib\site-packages\django\views\decorators\csrf.py", line 54, in wrapped_view
    return view_func(*args, **kwargs)
  File "E:\workspace\venv\django_ro_venv\lib\site-packages\django\views\generic\base.py", line 68, in view
    return self.dispatch(request, *args, **kwargs)
  File "E:\workspace\venv\django_ro_venv\lib\site-packages\rest_framework\views.py", line 495, in dispatch
    response = self.handle_exception(exc)
  File "E:\workspace\venv\django_ro_venv\lib\site-packages\rest_framework\views.py", line 455, in handle_exception
    self.raise_uncaught_exception(exc)
  File "E:\workspace\venv\django_ro_venv\lib\site-packages\rest_framework\views.py", line 492, in dispatch
    response = handler(request, *args, **kwargs)
  File "E:\workspace\project\django_ro\ro_operations\views.py", line 187, in get
    return Response(serializer.data)
  File "E:\workspace\venv\django_ro_venv\lib\site-packages\rest_framework\serializers.py", line 768, in data
    ret = super(ListSerializer, self).data
  File "E:\workspace\venv\django_ro_venv\lib\site-packages\rest_framework\serializers.py", line 262, in data
    self._data = self.to_representation(self.instance)
  File "E:\workspace\venv\django_ro_venv\lib\site-packages\rest_framework\serializers.py", line 686, in to_representation
    self.child.to_representation(item) for item in iterable
  File "E:\workspace\venv\django_ro_venv\lib\site-packages\rest_framework\serializers.py", line 686, in <listcomp>
    self.child.to_representation(item) for item in iterable
  File "E:\workspace\venv\django_ro_venv\lib\site-packages\rest_framework\serializers.py", line 530, in to_representation
    ret[field.field_name] = field.to_representation(attribute)
  File "E:\workspace\venv\django_ro_venv\lib\site-packages\rest_framework\fields.py", line 1233, in to_representation
    value = self.enforce_timezone(value)
  File "E:\workspace\venv\django_ro_venv\lib\site-packages\rest_framework\fields.py", line 1190, in enforce_timezone
    elif (field_timezone is None) and timezone.is_aware(value):
  File "E:\workspace\venv\django_ro_venv\lib\site-packages\django\utils\timezone.py", line 242, in is_aware
    return value.utcoffset() is not None
AttributeError: 'int' object has no attribute 'utcoffset'
2019-02-23 15:57:24,706 [Thread-2:2236] [django.request:228] [log:log_response] [ERROR]- Internal Server Error: /app_server_channels/
Traceback (most recent call last):
  File "E:\workspace\venv\django_ro_venv\lib\site-packages\django\core\handlers\exception.py", line 34, in inner
    response = get_response(request)
  File "E:\workspace\venv\django_ro_venv\lib\site-packages\django\core\handlers\base.py", line 126, in _get_response
    response = self.process_exception_by_middleware(e, request)
  File "E:\workspace\venv\django_ro_venv\lib\site-packages\django\core\handlers\base.py", line 124, in _get_response
    response = wrapped_callback(request, *callback_args, **callback_kwargs)
  File "E:\workspace\venv\django_ro_venv\lib\site-packages\django\views\decorators\csrf.py", line 54, in wrapped_view
    return view_func(*args, **kwargs)
  File "E:\workspace\venv\django_ro_venv\lib\site-packages\django\views\generic\base.py", line 68, in view
    return self.dispatch(request, *args, **kwargs)
  File "E:\workspace\venv\django_ro_venv\lib\site-packages\rest_framework\views.py", line 495, in dispatch
    response = self.handle_exception(exc)
  File "E:\workspace\venv\django_ro_venv\lib\site-packages\rest_framework\views.py", line 455, in handle_exception
    self.raise_uncaught_exception(exc)
  File "E:\workspace\venv\django_ro_venv\lib\site-packages\rest_framework\views.py", line 492, in dispatch
    response = handler(request, *args, **kwargs)
  File "E:\workspace\project\django_ro\ro_operations\views.py", line 187, in get
    return Response(serializer.data)
  File "E:\workspace\venv\django_ro_venv\lib\site-packages\rest_framework\serializers.py", line 768, in data
    ret = super(ListSerializer, self).data
  File "E:\workspace\venv\django_ro_venv\lib\site-packages\rest_framework\serializers.py", line 262, in data
    self._data = self.to_representation(self.instance)
  File "E:\workspace\venv\django_ro_venv\lib\site-packages\rest_framework\serializers.py", line 686, in to_representation
    self.child.to_representation(item) for item in iterable
  File "E:\workspace\venv\django_ro_venv\lib\site-packages\rest_framework\serializers.py", line 686, in <listcomp>
    self.child.to_representation(item) for item in iterable
  File "E:\workspace\venv\django_ro_venv\lib\site-packages\rest_framework\serializers.py", line 530, in to_representation
    ret[field.field_name] = field.to_representation(attribute)
  File "E:\workspace\venv\django_ro_venv\lib\site-packages\rest_framework\fields.py", line 1233, in to_representation
    value = self.enforce_timezone(value)
  File "E:\workspace\venv\django_ro_venv\lib\site-packages\rest_framework\fields.py", line 1190, in enforce_timezone
    elif (field_timezone is None) and timezone.is_aware(value):
  File "E:\workspace\venv\django_ro_venv\lib\site-packages\django\utils\timezone.py", line 242, in is_aware
    return value.utcoffset() is not None
AttributeError: 'int' object has no attribute 'utcoffset'
2019-02-23 15:57:33,973 [Thread-2:16196] [django.request:228] [log:log_response] [ERROR]- Internal Server Error: /app_server_channels/
Traceback (most recent call last):
  File "E:\workspace\venv\django_ro_venv\lib\site-packages\django\core\handlers\exception.py", line 34, in inner
    response = get_response(request)
  File "E:\workspace\venv\django_ro_venv\lib\site-packages\django\core\handlers\base.py", line 126, in _get_response
    response = self.process_exception_by_middleware(e, request)
  File "E:\workspace\venv\django_ro_venv\lib\site-packages\django\core\handlers\base.py", line 124, in _get_response
    response = wrapped_callback(request, *callback_args, **callback_kwargs)
  File "E:\workspace\venv\django_ro_venv\lib\site-packages\django\views\decorators\csrf.py", line 54, in wrapped_view
    return view_func(*args, **kwargs)
  File "E:\workspace\venv\django_ro_venv\lib\site-packages\django\views\generic\base.py", line 68, in view
    return self.dispatch(request, *args, **kwargs)
  File "E:\workspace\venv\django_ro_venv\lib\site-packages\rest_framework\views.py", line 495, in dispatch
    response = self.handle_exception(exc)
  File "E:\workspace\venv\django_ro_venv\lib\site-packages\rest_framework\views.py", line 455, in handle_exception
    self.raise_uncaught_exception(exc)
  File "E:\workspace\venv\django_ro_venv\lib\site-packages\rest_framework\views.py", line 492, in dispatch
    response = handler(request, *args, **kwargs)
  File "E:\workspace\project\django_ro\ro_operations\views.py", line 187, in get
    return Response(serializer.data)
  File "E:\workspace\venv\django_ro_venv\lib\site-packages\rest_framework\serializers.py", line 768, in data
    ret = super(ListSerializer, self).data
  File "E:\workspace\venv\django_ro_venv\lib\site-packages\rest_framework\serializers.py", line 262, in data
    self._data = self.to_representation(self.instance)
  File "E:\workspace\venv\django_ro_venv\lib\site-packages\rest_framework\serializers.py", line 686, in to_representation
    self.child.to_representation(item) for item in iterable
  File "E:\workspace\venv\django_ro_venv\lib\site-packages\rest_framework\serializers.py", line 686, in <listcomp>
    self.child.to_representation(item) for item in iterable
  File "E:\workspace\venv\django_ro_venv\lib\site-packages\rest_framework\serializers.py", line 530, in to_representation
    ret[field.field_name] = field.to_representation(attribute)
  File "E:\workspace\venv\django_ro_venv\lib\site-packages\rest_framework\fields.py", line 1233, in to_representation
    value = self.enforce_timezone(value)
  File "E:\workspace\venv\django_ro_venv\lib\site-packages\rest_framework\fields.py", line 1190, in enforce_timezone
    elif (field_timezone is None) and timezone.is_aware(value):
  File "E:\workspace\venv\django_ro_venv\lib\site-packages\django\utils\timezone.py", line 242, in is_aware
    return value.utcoffset() is not None
AttributeError: 'int' object has no attribute 'utcoffset'
2019-02-23 15:58:04,870 [Thread-2:16196] [django.request:228] [log:log_response] [ERROR]- Internal Server Error: /app_server_channels/
Traceback (most recent call last):
  File "E:\workspace\venv\django_ro_venv\lib\site-packages\django\core\handlers\exception.py", line 34, in inner
    response = get_response(request)
  File "E:\workspace\venv\django_ro_venv\lib\site-packages\django\core\handlers\base.py", line 126, in _get_response
    response = self.process_exception_by_middleware(e, request)
  File "E:\workspace\venv\django_ro_venv\lib\site-packages\django\core\handlers\base.py", line 124, in _get_response
    response = wrapped_callback(request, *callback_args, **callback_kwargs)
  File "E:\workspace\venv\django_ro_venv\lib\site-packages\django\views\decorators\csrf.py", line 54, in wrapped_view
    return view_func(*args, **kwargs)
  File "E:\workspace\venv\django_ro_venv\lib\site-packages\django\views\generic\base.py", line 68, in view
    return self.dispatch(request, *args, **kwargs)
  File "E:\workspace\venv\django_ro_venv\lib\site-packages\rest_framework\views.py", line 495, in dispatch
    response = self.handle_exception(exc)
  File "E:\workspace\venv\django_ro_venv\lib\site-packages\rest_framework\views.py", line 455, in handle_exception
    self.raise_uncaught_exception(exc)
  File "E:\workspace\venv\django_ro_venv\lib\site-packages\rest_framework\views.py", line 492, in dispatch
    response = handler(request, *args, **kwargs)
  File "E:\workspace\project\django_ro\ro_operations\views.py", line 187, in get
    return Response(serializer.data)
  File "E:\workspace\venv\django_ro_venv\lib\site-packages\rest_framework\serializers.py", line 768, in data
    ret = super(ListSerializer, self).data
  File "E:\workspace\venv\django_ro_venv\lib\site-packages\rest_framework\serializers.py", line 262, in data
    self._data = self.to_representation(self.instance)
  File "E:\workspace\venv\django_ro_venv\lib\site-packages\rest_framework\serializers.py", line 686, in to_representation
    self.child.to_representation(item) for item in iterable
  File "E:\workspace\venv\django_ro_venv\lib\site-packages\rest_framework\serializers.py", line 686, in <listcomp>
    self.child.to_representation(item) for item in iterable
  File "E:\workspace\venv\django_ro_venv\lib\site-packages\rest_framework\serializers.py", line 530, in to_representation
    ret[field.field_name] = field.to_representation(attribute)
  File "E:\workspace\venv\django_ro_venv\lib\site-packages\rest_framework\fields.py", line 1233, in to_representation
    value = self.enforce_timezone(value)
  File "E:\workspace\venv\django_ro_venv\lib\site-packages\rest_framework\fields.py", line 1190, in enforce_timezone
    elif (field_timezone is None) and timezone.is_aware(value):
  File "E:\workspace\venv\django_ro_venv\lib\site-packages\django\utils\timezone.py", line 242, in is_aware
    return value.utcoffset() is not None
AttributeError: 'int' object has no attribute 'utcoffset'
2019-02-23 15:58:14,992 [Thread-2:16196] [django.request:228] [log:log_response] [ERROR]- Internal Server Error: /app_server_channels/
Traceback (most recent call last):
  File "E:\workspace\venv\django_ro_venv\lib\site-packages\django\core\handlers\exception.py", line 34, in inner
    response = get_response(request)
  File "E:\workspace\venv\django_ro_venv\lib\site-packages\django\core\handlers\base.py", line 126, in _get_response
    response = self.process_exception_by_middleware(e, request)
  File "E:\workspace\venv\django_ro_venv\lib\site-packages\django\core\handlers\base.py", line 124, in _get_response
    response = wrapped_callback(request, *callback_args, **callback_kwargs)
  File "E:\workspace\venv\django_ro_venv\lib\site-packages\django\views\decorators\csrf.py", line 54, in wrapped_view
    return view_func(*args, **kwargs)
  File "E:\workspace\venv\django_ro_venv\lib\site-packages\django\views\generic\base.py", line 68, in view
    return self.dispatch(request, *args, **kwargs)
  File "E:\workspace\venv\django_ro_venv\lib\site-packages\rest_framework\views.py", line 495, in dispatch
    response = self.handle_exception(exc)
  File "E:\workspace\venv\django_ro_venv\lib\site-packages\rest_framework\views.py", line 455, in handle_exception
    self.raise_uncaught_exception(exc)
  File "E:\workspace\venv\django_ro_venv\lib\site-packages\rest_framework\views.py", line 492, in dispatch
    response = handler(request, *args, **kwargs)
  File "E:\workspace\project\django_ro\ro_operations\views.py", line 187, in get
    return Response(serializer.data)
  File "E:\workspace\venv\django_ro_venv\lib\site-packages\rest_framework\serializers.py", line 768, in data
    ret = super(ListSerializer, self).data
  File "E:\workspace\venv\django_ro_venv\lib\site-packages\rest_framework\serializers.py", line 262, in data
    self._data = self.to_representation(self.instance)
  File "E:\workspace\venv\django_ro_venv\lib\site-packages\rest_framework\serializers.py", line 686, in to_representation
    self.child.to_representation(item) for item in iterable
  File "E:\workspace\venv\django_ro_venv\lib\site-packages\rest_framework\serializers.py", line 686, in <listcomp>
    self.child.to_representation(item) for item in iterable
  File "E:\workspace\venv\django_ro_venv\lib\site-packages\rest_framework\serializers.py", line 530, in to_representation
    ret[field.field_name] = field.to_representation(attribute)
  File "E:\workspace\venv\django_ro_venv\lib\site-packages\rest_framework\fields.py", line 1233, in to_representation
    value = self.enforce_timezone(value)
  File "E:\workspace\venv\django_ro_venv\lib\site-packages\rest_framework\fields.py", line 1190, in enforce_timezone
    elif (field_timezone is None) and timezone.is_aware(value):
  File "E:\workspace\venv\django_ro_venv\lib\site-packages\django\utils\timezone.py", line 242, in is_aware
    return value.utcoffset() is not None
AttributeError: 'int' object has no attribute 'utcoffset'
2019-02-23 15:58:22,382 [Thread-2:16196] [django.request:228] [log:log_response] [ERROR]- Internal Server Error: /app_server_channels/
Traceback (most recent call last):
  File "E:\workspace\venv\django_ro_venv\lib\site-packages\django\core\handlers\exception.py", line 34, in inner
    response = get_response(request)
  File "E:\workspace\venv\django_ro_venv\lib\site-packages\django\core\handlers\base.py", line 126, in _get_response
    response = self.process_exception_by_middleware(e, request)
  File "E:\workspace\venv\django_ro_venv\lib\site-packages\django\core\handlers\base.py", line 124, in _get_response
    response = wrapped_callback(request, *callback_args, **callback_kwargs)
  File "E:\workspace\venv\django_ro_venv\lib\site-packages\django\views\decorators\csrf.py", line 54, in wrapped_view
    return view_func(*args, **kwargs)
  File "E:\workspace\venv\django_ro_venv\lib\site-packages\django\views\generic\base.py", line 68, in view
    return self.dispatch(request, *args, **kwargs)
  File "E:\workspace\venv\django_ro_venv\lib\site-packages\rest_framework\views.py", line 495, in dispatch
    response = self.handle_exception(exc)
  File "E:\workspace\venv\django_ro_venv\lib\site-packages\rest_framework\views.py", line 455, in handle_exception
    self.raise_uncaught_exception(exc)
  File "E:\workspace\venv\django_ro_venv\lib\site-packages\rest_framework\views.py", line 492, in dispatch
    response = handler(request, *args, **kwargs)
  File "E:\workspace\project\django_ro\ro_operations\views.py", line 187, in get
    return Response(serializer.data)
  File "E:\workspace\venv\django_ro_venv\lib\site-packages\rest_framework\serializers.py", line 768, in data
    ret = super(ListSerializer, self).data
  File "E:\workspace\venv\django_ro_venv\lib\site-packages\rest_framework\serializers.py", line 262, in data
    self._data = self.to_representation(self.instance)
  File "E:\workspace\venv\django_ro_venv\lib\site-packages\rest_framework\serializers.py", line 686, in to_representation
    self.child.to_representation(item) for item in iterable
  File "E:\workspace\venv\django_ro_venv\lib\site-packages\rest_framework\serializers.py", line 686, in <listcomp>
    self.child.to_representation(item) for item in iterable
  File "E:\workspace\venv\django_ro_venv\lib\site-packages\rest_framework\serializers.py", line 530, in to_representation
    ret[field.field_name] = field.to_representation(attribute)
  File "E:\workspace\venv\django_ro_venv\lib\site-packages\rest_framework\fields.py", line 1233, in to_representation
    value = self.enforce_timezone(value)
  File "E:\workspace\venv\django_ro_venv\lib\site-packages\rest_framework\fields.py", line 1190, in enforce_timezone
    elif (field_timezone is None) and timezone.is_aware(value):
  File "E:\workspace\venv\django_ro_venv\lib\site-packages\django\utils\timezone.py", line 242, in is_aware
    return value.utcoffset() is not None
AttributeError: 'int' object has no attribute 'utcoffset'
2019-02-23 16:01:32,790 [Thread-2:16196] [django.request:228] [log:log_response] [ERROR]- Internal Server Error: /app_server_channels/
Traceback (most recent call last):
  File "E:\workspace\venv\django_ro_venv\lib\site-packages\django\core\handlers\exception.py", line 34, in inner
    response = get_response(request)
  File "E:\workspace\venv\django_ro_venv\lib\site-packages\django\core\handlers\base.py", line 126, in _get_response
    response = self.process_exception_by_middleware(e, request)
  File "E:\workspace\venv\django_ro_venv\lib\site-packages\django\core\handlers\base.py", line 124, in _get_response
    response = wrapped_callback(request, *callback_args, **callback_kwargs)
  File "E:\workspace\venv\django_ro_venv\lib\site-packages\django\views\decorators\csrf.py", line 54, in wrapped_view
    return view_func(*args, **kwargs)
  File "E:\workspace\venv\django_ro_venv\lib\site-packages\django\views\generic\base.py", line 68, in view
    return self.dispatch(request, *args, **kwargs)
  File "E:\workspace\venv\django_ro_venv\lib\site-packages\rest_framework\views.py", line 495, in dispatch
    response = self.handle_exception(exc)
  File "E:\workspace\venv\django_ro_venv\lib\site-packages\rest_framework\views.py", line 455, in handle_exception
    self.raise_uncaught_exception(exc)
  File "E:\workspace\venv\django_ro_venv\lib\site-packages\rest_framework\views.py", line 492, in dispatch
    response = handler(request, *args, **kwargs)
  File "E:\workspace\project\django_ro\ro_operations\views.py", line 187, in get
    return Response(serializer.data)
  File "E:\workspace\venv\django_ro_venv\lib\site-packages\rest_framework\serializers.py", line 768, in data
    ret = super(ListSerializer, self).data
  File "E:\workspace\venv\django_ro_venv\lib\site-packages\rest_framework\serializers.py", line 262, in data
    self._data = self.to_representation(self.instance)
  File "E:\workspace\venv\django_ro_venv\lib\site-packages\rest_framework\serializers.py", line 686, in to_representation
    self.child.to_representation(item) for item in iterable
  File "E:\workspace\venv\django_ro_venv\lib\site-packages\rest_framework\serializers.py", line 686, in <listcomp>
    self.child.to_representation(item) for item in iterable
  File "E:\workspace\venv\django_ro_venv\lib\site-packages\rest_framework\serializers.py", line 530, in to_representation
    ret[field.field_name] = field.to_representation(attribute)
  File "E:\workspace\venv\django_ro_venv\lib\site-packages\rest_framework\fields.py", line 1233, in to_representation
    value = self.enforce_timezone(value)
  File "E:\workspace\venv\django_ro_venv\lib\site-packages\rest_framework\fields.py", line 1190, in enforce_timezone
    elif (field_timezone is None) and timezone.is_aware(value):
  File "E:\workspace\venv\django_ro_venv\lib\site-packages\django\utils\timezone.py", line 242, in is_aware
    return value.utcoffset() is not None
AttributeError: 'int' object has no attribute 'utcoffset'
2019-02-23 16:01:33,833 [Thread-2:16196] [django.request:228] [log:log_response] [ERROR]- Internal Server Error: /app_server_channels/
Traceback (most recent call last):
  File "E:\workspace\venv\django_ro_venv\lib\site-packages\django\core\handlers\exception.py", line 34, in inner
    response = get_response(request)
  File "E:\workspace\venv\django_ro_venv\lib\site-packages\django\core\handlers\base.py", line 126, in _get_response
    response = self.process_exception_by_middleware(e, request)
  File "E:\workspace\venv\django_ro_venv\lib\site-packages\django\core\handlers\base.py", line 124, in _get_response
    response = wrapped_callback(request, *callback_args, **callback_kwargs)
  File "E:\workspace\venv\django_ro_venv\lib\site-packages\django\views\decorators\csrf.py", line 54, in wrapped_view
    return view_func(*args, **kwargs)
  File "E:\workspace\venv\django_ro_venv\lib\site-packages\django\views\generic\base.py", line 68, in view
    return self.dispatch(request, *args, **kwargs)
  File "E:\workspace\venv\django_ro_venv\lib\site-packages\rest_framework\views.py", line 495, in dispatch
    response = self.handle_exception(exc)
  File "E:\workspace\venv\django_ro_venv\lib\site-packages\rest_framework\views.py", line 455, in handle_exception
    self.raise_uncaught_exception(exc)
  File "E:\workspace\venv\django_ro_venv\lib\site-packages\rest_framework\views.py", line 492, in dispatch
    response = handler(request, *args, **kwargs)
  File "E:\workspace\project\django_ro\ro_operations\views.py", line 187, in get
    return Response(serializer.data)
  File "E:\workspace\venv\django_ro_venv\lib\site-packages\rest_framework\serializers.py", line 768, in data
    ret = super(ListSerializer, self).data
  File "E:\workspace\venv\django_ro_venv\lib\site-packages\rest_framework\serializers.py", line 262, in data
    self._data = self.to_representation(self.instance)
  File "E:\workspace\venv\django_ro_venv\lib\site-packages\rest_framework\serializers.py", line 686, in to_representation
    self.child.to_representation(item) for item in iterable
  File "E:\workspace\venv\django_ro_venv\lib\site-packages\rest_framework\serializers.py", line 686, in <listcomp>
    self.child.to_representation(item) for item in iterable
  File "E:\workspace\venv\django_ro_venv\lib\site-packages\rest_framework\serializers.py", line 530, in to_representation
    ret[field.field_name] = field.to_representation(attribute)
  File "E:\workspace\venv\django_ro_venv\lib\site-packages\rest_framework\fields.py", line 1233, in to_representation
    value = self.enforce_timezone(value)
  File "E:\workspace\venv\django_ro_venv\lib\site-packages\rest_framework\fields.py", line 1190, in enforce_timezone
    elif (field_timezone is None) and timezone.is_aware(value):
  File "E:\workspace\venv\django_ro_venv\lib\site-packages\django\utils\timezone.py", line 242, in is_aware
    return value.utcoffset() is not None
AttributeError: 'int' object has no attribute 'utcoffset'
2019-02-25 10:55:14,374 [Thread-3:1336] [django.request:228] [log:log_response] [WARNING]- Forbidden: /welfares/
2019-02-25 11:06:17,130 [Thread-2:15112] [django.request:228] [log:log_response] [ERROR]- Internal Server Error: /app_managements/
Traceback (most recent call last):
  File "E:\workspace\venv\django_ro_venv\lib\site-packages\django\core\handlers\exception.py", line 34, in inner
    response = get_response(request)
  File "E:\workspace\venv\django_ro_venv\lib\site-packages\django\core\handlers\base.py", line 126, in _get_response
    response = self.process_exception_by_middleware(e, request)
  File "E:\workspace\venv\django_ro_venv\lib\site-packages\django\core\handlers\base.py", line 124, in _get_response
    response = wrapped_callback(request, *callback_args, **callback_kwargs)
  File "E:\workspace\venv\django_ro_venv\lib\site-packages\django\views\decorators\csrf.py", line 54, in wrapped_view
    return view_func(*args, **kwargs)
  File "E:\workspace\venv\django_ro_venv\lib\site-packages\django\views\generic\base.py", line 68, in view
    return self.dispatch(request, *args, **kwargs)
  File "E:\workspace\venv\django_ro_venv\lib\site-packages\rest_framework\views.py", line 495, in dispatch
    response = self.handle_exception(exc)
  File "E:\workspace\venv\django_ro_venv\lib\site-packages\rest_framework\views.py", line 455, in handle_exception
    self.raise_uncaught_exception(exc)
  File "E:\workspace\venv\django_ro_venv\lib\site-packages\rest_framework\views.py", line 492, in dispatch
    response = handler(request, *args, **kwargs)
  File "E:\workspace\project\django_ro\ro_operations\views.py", line 184, in get
    app_manage_list = AppManage.objects.all.filter(gametypeno=50)
AttributeError: 'function' object has no attribute 'filter'
2019-02-25 17:06:39,398 [Thread-2:11616] [django.request:228] [log:log_response] [WARNING]- Bad Request: /app_server_channels/39347/
2019-02-25 17:07:08,505 [Thread-2:13788] [django.request:228] [log:log_response] [WARNING]- Bad Request: /app_server_channels/39347/
2019-02-25 17:17:18,935 [Thread-4:1516] [django.request:228] [log:log_response] [WARNING]- Bad Request: /app_server_channels/39347/
2019-02-25 17:21:09,795 [Thread-2:13180] [django.request:228] [log:log_response] [WARNING]- Bad Request: /app_server_channels/39347/
2019-02-25 17:25:59,935 [Thread-2:5996] [django.request:228] [log:log_response] [WARNING]- Bad Request: /app_server_channels/39347/
2019-02-25 17:26:44,646 [Thread-2:888] [django.request:228] [log:log_response] [ERROR]- Internal Server Error: /app_server_channels/39347/
Traceback (most recent call last):
  File "E:\workspace\venv\django_ro_venv\lib\site-packages\django\core\handlers\exception.py", line 34, in inner
    response = get_response(request)
  File "E:\workspace\venv\django_ro_venv\lib\site-packages\django\core\handlers\base.py", line 126, in _get_response
    response = self.process_exception_by_middleware(e, request)
  File "E:\workspace\venv\django_ro_venv\lib\site-packages\django\core\handlers\base.py", line 124, in _get_response
    response = wrapped_callback(request, *callback_args, **callback_kwargs)
  File "E:\workspace\venv\django_ro_venv\lib\site-packages\django\views\decorators\csrf.py", line 54, in wrapped_view
    return view_func(*args, **kwargs)
  File "E:\workspace\venv\django_ro_venv\lib\site-packages\django\views\generic\base.py", line 68, in view
    return self.dispatch(request, *args, **kwargs)
  File "E:\workspace\venv\django_ro_venv\lib\site-packages\rest_framework\views.py", line 495, in dispatch
    response = self.handle_exception(exc)
  File "E:\workspace\venv\django_ro_venv\lib\site-packages\rest_framework\views.py", line 455, in handle_exception
    self.raise_uncaught_exception(exc)
  File "E:\workspace\venv\django_ro_venv\lib\site-packages\rest_framework\views.py", line 492, in dispatch
    response = handler(request, *args, **kwargs)
  File "E:\workspace\project\django_ro\ro_operations\views.py", line 236, in put
    print(serializer.errors)
UnboundLocalError: local variable 'serializer' referenced before assignment
2019-02-25 17:27:23,959 [Thread-2:12248] [django.request:228] [log:log_response] [WARNING]- Bad Request: /app_server_channels/39347/
2019-02-26 10:58:41,734 [Thread-6:7128] [django.request:228] [log:log_response] [WARNING]- Forbidden: /welfares/
2019-02-26 16:11:35,839 [Thread-2:12680] [django.request:228] [log:log_response] [WARNING]- Bad Request: /app_server_channels/39347/
2019-02-26 16:18:38,059 [Thread-5:8652] [django.request:228] [log:log_response] [WARNING]- Bad Request: /app_server_channels/39347/
2019-02-26 16:21:08,327 [Thread-5:8652] [django.request:228] [log:log_response] [WARNING]- Bad Request: /app_server_channels/39347/
2019-02-26 16:36:38,423 [Thread-5:8652] [django.request:228] [log:log_response] [WARNING]- Bad Request: /app_server_channels/39347/
2019-02-26 16:38:29,334 [Thread-2:6904] [django.request:228] [log:log_response] [WARNING]- Bad Request: /app_server_channels/39347/
2019-02-26 16:59:19,292 [Thread-4:7540] [django.request:228] [log:log_response] [WARNING]- Bad Request: /app_server_channels/39347/
2019-02-27 10:57:20,970 [Thread-2:4388] [django.request:228] [log:log_response] [WARNING]- Forbidden: /welfares/
2019-02-27 15:26:30,615 [Thread-2:1436] [django.request:228] [log:log_response] [ERROR]- Internal Server Error: /set_open/
Traceback (most recent call last):
  File "E:\workspace\venv\django_ro_venv\lib\site-packages\django\core\handlers\exception.py", line 34, in inner
    response = get_response(request)
  File "E:\workspace\venv\django_ro_venv\lib\site-packages\django\core\handlers\base.py", line 126, in _get_response
    response = self.process_exception_by_middleware(e, request)
  File "E:\workspace\venv\django_ro_venv\lib\site-packages\django\core\handlers\base.py", line 124, in _get_response
    response = wrapped_callback(request, *callback_args, **callback_kwargs)
  File "E:\workspace\venv\django_ro_venv\lib\site-packages\django\views\decorators\csrf.py", line 54, in wrapped_view
    return view_func(*args, **kwargs)
  File "E:\workspace\venv\django_ro_venv\lib\site-packages\django\views\generic\base.py", line 68, in view
    return self.dispatch(request, *args, **kwargs)
  File "E:\workspace\venv\django_ro_venv\lib\site-packages\rest_framework\views.py", line 495, in dispatch
    response = self.handle_exception(exc)
  File "E:\workspace\venv\django_ro_venv\lib\site-packages\rest_framework\views.py", line 455, in handle_exception
    self.raise_uncaught_exception(exc)
  File "E:\workspace\venv\django_ro_venv\lib\site-packages\rest_framework\views.py", line 492, in dispatch
    response = handler(request, *args, **kwargs)
  File "E:\workspace\venv\django_ro_venv\lib\site-packages\rest_framework\decorators.py", line 54, in handler
    return func(*args, **kwargs)
  File "E:\workspace\project\django_ro\ro_operations\views.py", line 134, in set_open
    id_list = [each.id for each in selected_zone]
TypeError: 'NoneType' object is not iterable
2019-02-27 15:27:45,873 [Thread-3:13440] [django.request:228] [log:log_response] [ERROR]- Internal Server Error: /set_open/
Traceback (most recent call last):
  File "E:\workspace\venv\django_ro_venv\lib\site-packages\django\core\handlers\exception.py", line 34, in inner
    response = get_response(request)
  File "E:\workspace\venv\django_ro_venv\lib\site-packages\django\core\handlers\base.py", line 126, in _get_response
    response = self.process_exception_by_middleware(e, request)
  File "E:\workspace\venv\django_ro_venv\lib\site-packages\django\core\handlers\base.py", line 124, in _get_response
    response = wrapped_callback(request, *callback_args, **callback_kwargs)
  File "E:\workspace\venv\django_ro_venv\lib\site-packages\django\views\decorators\csrf.py", line 54, in wrapped_view
    return view_func(*args, **kwargs)
  File "E:\workspace\venv\django_ro_venv\lib\site-packages\django\views\generic\base.py", line 68, in view
    return self.dispatch(request, *args, **kwargs)
  File "E:\workspace\venv\django_ro_venv\lib\site-packages\rest_framework\views.py", line 495, in dispatch
    response = self.handle_exception(exc)
  File "E:\workspace\venv\django_ro_venv\lib\site-packages\rest_framework\views.py", line 455, in handle_exception
    self.raise_uncaught_exception(exc)
  File "E:\workspace\venv\django_ro_venv\lib\site-packages\rest_framework\views.py", line 492, in dispatch
    response = handler(request, *args, **kwargs)
  File "E:\workspace\venv\django_ro_venv\lib\site-packages\rest_framework\decorators.py", line 54, in handler
    return func(*args, **kwargs)
  File "E:\workspace\project\django_ro\ro_operations\views.py", line 134, in set_open
    id_list = [each.id for each in selected_zone]
TypeError: 'NoneType' object is not iterable
2019-02-27 15:28:42,510 [Thread-3:13440] [django.request:228] [log:log_response] [ERROR]- Internal Server Error: /set_open/
Traceback (most recent call last):
  File "E:\workspace\venv\django_ro_venv\lib\site-packages\django\core\handlers\exception.py", line 34, in inner
    response = get_response(request)
  File "E:\workspace\venv\django_ro_venv\lib\site-packages\django\core\handlers\base.py", line 126, in _get_response
    response = self.process_exception_by_middleware(e, request)
  File "E:\workspace\venv\django_ro_venv\lib\site-packages\django\core\handlers\base.py", line 124, in _get_response
    response = wrapped_callback(request, *callback_args, **callback_kwargs)
  File "E:\workspace\venv\django_ro_venv\lib\site-packages\django\views\decorators\csrf.py", line 54, in wrapped_view
    return view_func(*args, **kwargs)
  File "E:\workspace\venv\django_ro_venv\lib\site-packages\django\views\generic\base.py", line 68, in view
    return self.dispatch(request, *args, **kwargs)
  File "E:\workspace\venv\django_ro_venv\lib\site-packages\rest_framework\views.py", line 495, in dispatch
    response = self.handle_exception(exc)
  File "E:\workspace\venv\django_ro_venv\lib\site-packages\rest_framework\views.py", line 455, in handle_exception
    self.raise_uncaught_exception(exc)
  File "E:\workspace\venv\django_ro_venv\lib\site-packages\rest_framework\views.py", line 492, in dispatch
    response = handler(request, *args, **kwargs)
  File "E:\workspace\venv\django_ro_venv\lib\site-packages\rest_framework\decorators.py", line 54, in handler
    return func(*args, **kwargs)
  File "E:\workspace\project\django_ro\ro_operations\views.py", line 134, in set_open
    id_list = [each.id for each in selected_zone]
  File "E:\workspace\project\django_ro\ro_operations\views.py", line 134, in <listcomp>
    id_list = [each.id for each in selected_zone]
AttributeError: 'dict' object has no attribute 'id'
2019-02-27 15:30:57,130 [Thread-2:13172] [django.request:228] [log:log_response] [WARNING]- Bad Request: /set_open/
2019-02-28 13:32:30,398 [Thread-5:11112] [django.request:228] [log:log_response] [WARNING]- Forbidden: /welfares/
2019-03-01 17:18:42,227 [Thread-5:13996] [django.request:228] [log:log_response] [ERROR]- Internal Server Error: /delete_open_plan/
Traceback (most recent call last):
  File "E:\workspace\venv\django_ro_venv\lib\site-packages\django\core\handlers\exception.py", line 34, in inner
    response = get_response(request)
  File "E:\workspace\venv\django_ro_venv\lib\site-packages\django\core\handlers\base.py", line 126, in _get_response
    response = self.process_exception_by_middleware(e, request)
  File "E:\workspace\venv\django_ro_venv\lib\site-packages\django\core\handlers\base.py", line 124, in _get_response
    response = wrapped_callback(request, *callback_args, **callback_kwargs)
  File "E:\workspace\venv\django_ro_venv\lib\site-packages\django\views\decorators\csrf.py", line 54, in wrapped_view
    return view_func(*args, **kwargs)
  File "E:\workspace\venv\django_ro_venv\lib\site-packages\django\views\generic\base.py", line 68, in view
    return self.dispatch(request, *args, **kwargs)
  File "E:\workspace\venv\django_ro_venv\lib\site-packages\rest_framework\views.py", line 495, in dispatch
    response = self.handle_exception(exc)
  File "E:\workspace\venv\django_ro_venv\lib\site-packages\rest_framework\views.py", line 455, in handle_exception
    self.raise_uncaught_exception(exc)
  File "E:\workspace\venv\django_ro_venv\lib\site-packages\rest_framework\views.py", line 492, in dispatch
    response = handler(request, *args, **kwargs)
  File "E:\workspace\venv\django_ro_venv\lib\site-packages\rest_framework\decorators.py", line 54, in handler
    return func(*args, **kwargs)
  File "E:\workspace\project\django_ro\ro_operations\views.py", line 170, in delete_open_plan
    app_server_channel_list = AppServerChannel.objects.filter(zoneidx=zoneidx) if by_zone else AppServerChannel.objects.filter(id=id)
  File "E:\workspace\venv\django_ro_venv\lib\site-packages\django\db\models\manager.py", line 82, in manager_method
    return getattr(self.get_queryset(), name)(*args, **kwargs)
  File "E:\workspace\venv\django_ro_venv\lib\site-packages\django\db\models\query.py", line 844, in filter
    return self._filter_or_exclude(False, *args, **kwargs)
  File "E:\workspace\venv\django_ro_venv\lib\site-packages\django\db\models\query.py", line 862, in _filter_or_exclude
    clone.query.add_q(Q(*args, **kwargs))
  File "E:\workspace\venv\django_ro_venv\lib\site-packages\django\db\models\sql\query.py", line 1263, in add_q
    clause, _ = self._add_q(q_object, self.used_aliases)
  File "E:\workspace\venv\django_ro_venv\lib\site-packages\django\db\models\sql\query.py", line 1287, in _add_q
    split_subq=split_subq,
  File "E:\workspace\venv\django_ro_venv\lib\site-packages\django\db\models\sql\query.py", line 1225, in build_filter
    condition = self.build_lookup(lookups, col, value)
  File "E:\workspace\venv\django_ro_venv\lib\site-packages\django\db\models\sql\query.py", line 1096, in build_lookup
    lookup = lookup_class(lhs, rhs)
  File "E:\workspace\venv\django_ro_venv\lib\site-packages\django\db\models\lookups.py", line 20, in __init__
    self.rhs = self.get_prep_lookup()
  File "E:\workspace\venv\django_ro_venv\lib\site-packages\django\db\models\lookups.py", line 70, in get_prep_lookup
    return self.lhs.output_field.get_prep_value(self.rhs)
  File "E:\workspace\venv\django_ro_venv\lib\site-packages\django\db\models\fields\__init__.py", line 1807, in get_prep_value
    return int(value)
ValueError: invalid literal for int() with base 10: ''
2019-03-02 14:45:29,635 [Thread-2:13516] [django.request:228] [log:log_response] [WARNING]- Forbidden: /welfares/
2019-03-02 16:34:43,064 [Thread-2:14980] [django.request:228] [log:log_response] [WARNING]- Not Found: /app_server_channels/undefined/
2019-03-02 17:02:13,909 [Thread-2:9428] [django.request:228] [log:log_response] [WARNING]- Method Not Allowed: /app_server_channels/
2019-03-02 17:04:05,965 [Thread-2:9428] [django.request:228] [log:log_response] [ERROR]- Internal Server Error: /app_server_channels/39347/
Traceback (most recent call last):
  File "E:\workspace\venv\django_ro_venv\lib\site-packages\django\core\handlers\exception.py", line 34, in inner
    response = get_response(request)
  File "E:\workspace\venv\django_ro_venv\lib\site-packages\django\core\handlers\base.py", line 126, in _get_response
    response = self.process_exception_by_middleware(e, request)
  File "E:\workspace\venv\django_ro_venv\lib\site-packages\django\core\handlers\base.py", line 124, in _get_response
    response = wrapped_callback(request, *callback_args, **callback_kwargs)
  File "E:\workspace\venv\django_ro_venv\lib\site-packages\django\views\decorators\csrf.py", line 54, in wrapped_view
    return view_func(*args, **kwargs)
  File "E:\workspace\venv\django_ro_venv\lib\site-packages\django\views\generic\base.py", line 68, in view
    return self.dispatch(request, *args, **kwargs)
  File "E:\workspace\venv\django_ro_venv\lib\site-packages\rest_framework\views.py", line 497, in dispatch
    self.response = self.finalize_response(request, response, *args, **kwargs)
  File "E:\workspace\venv\django_ro_venv\lib\site-packages\rest_framework\views.py", line 412, in finalize_response
    % type(response)
AssertionError: Expected a `Response`, `HttpResponse` or `HttpStreamingResponse` to be returned from the view, but received a `<class 'NoneType'>`
2019-03-02 17:04:41,246 [Thread-2:8188] [django.request:228] [log:log_response] [ERROR]- Internal Server Error: /app_server_channels/39347/
Traceback (most recent call last):
  File "E:\workspace\venv\django_ro_venv\lib\site-packages\django\core\handlers\exception.py", line 34, in inner
    response = get_response(request)
  File "E:\workspace\venv\django_ro_venv\lib\site-packages\django\core\handlers\base.py", line 126, in _get_response
    response = self.process_exception_by_middleware(e, request)
  File "E:\workspace\venv\django_ro_venv\lib\site-packages\django\core\handlers\base.py", line 124, in _get_response
    response = wrapped_callback(request, *callback_args, **callback_kwargs)
  File "E:\workspace\venv\django_ro_venv\lib\site-packages\django\views\decorators\csrf.py", line 54, in wrapped_view
    return view_func(*args, **kwargs)
  File "E:\workspace\venv\django_ro_venv\lib\site-packages\django\views\generic\base.py", line 68, in view
    return self.dispatch(request, *args, **kwargs)
  File "E:\workspace\venv\django_ro_venv\lib\site-packages\rest_framework\views.py", line 497, in dispatch
    self.response = self.finalize_response(request, response, *args, **kwargs)
  File "E:\workspace\venv\django_ro_venv\lib\site-packages\rest_framework\views.py", line 412, in finalize_response
    % type(response)
AssertionError: Expected a `Response`, `HttpResponse` or `HttpStreamingResponse` to be returned from the view, but received a `<class 'NoneType'>`
2019-03-02 17:05:24,465 [Thread-2:11940] [django.request:228] [log:log_response] [ERROR]- Internal Server Error: /app_server_channels/39347/
Traceback (most recent call last):
  File "E:\workspace\venv\django_ro_venv\lib\site-packages\rest_framework\request.py", line 412, in __getattr__
    return getattr(self._request, attr)
AttributeError: 'WSGIRequest' object has no attribute 'DELETE'

During handling of the above exception, another exception occurred:

Traceback (most recent call last):
  File "E:\workspace\venv\django_ro_venv\lib\site-packages\django\core\handlers\exception.py", line 34, in inner
    response = get_response(request)
  File "E:\workspace\venv\django_ro_venv\lib\site-packages\django\core\handlers\base.py", line 126, in _get_response
    response = self.process_exception_by_middleware(e, request)
  File "E:\workspace\venv\django_ro_venv\lib\site-packages\django\core\handlers\base.py", line 124, in _get_response
    response = wrapped_callback(request, *callback_args, **callback_kwargs)
  File "E:\workspace\venv\django_ro_venv\lib\site-packages\django\views\decorators\csrf.py", line 54, in wrapped_view
    return view_func(*args, **kwargs)
  File "E:\workspace\venv\django_ro_venv\lib\site-packages\django\views\generic\base.py", line 68, in view
    return self.dispatch(request, *args, **kwargs)
  File "E:\workspace\venv\django_ro_venv\lib\site-packages\rest_framework\views.py", line 495, in dispatch
    response = self.handle_exception(exc)
  File "E:\workspace\venv\django_ro_venv\lib\site-packages\rest_framework\views.py", line 455, in handle_exception
    self.raise_uncaught_exception(exc)
  File "E:\workspace\venv\django_ro_venv\lib\site-packages\rest_framework\views.py", line 492, in dispatch
    response = handler(request, *args, **kwargs)
  File "E:\workspace\project\django_ro\ro_operations\views.py", line 366, in delete
    print(request.DELETE)
  File "E:\workspace\venv\django_ro_venv\lib\site-packages\rest_framework\request.py", line 414, in __getattr__
    return self.__getattribute__(attr)
AttributeError: 'Request' object has no attribute 'DELETE'
2019-03-02 17:05:48,493 [Thread-2:11940] [django.request:228] [log:log_response] [ERROR]- Internal Server Error: /app_server_channels/39347/
Traceback (most recent call last):
  File "E:\workspace\venv\django_ro_venv\lib\site-packages\rest_framework\request.py", line 412, in __getattr__
    return getattr(self._request, attr)
AttributeError: 'WSGIRequest' object has no attribute 'DELETE'

During handling of the above exception, another exception occurred:

Traceback (most recent call last):
  File "E:\workspace\venv\django_ro_venv\lib\site-packages\django\core\handlers\exception.py", line 34, in inner
    response = get_response(request)
  File "E:\workspace\venv\django_ro_venv\lib\site-packages\django\core\handlers\base.py", line 126, in _get_response
    response = self.process_exception_by_middleware(e, request)
  File "E:\workspace\venv\django_ro_venv\lib\site-packages\django\core\handlers\base.py", line 124, in _get_response
    response = wrapped_callback(request, *callback_args, **callback_kwargs)
  File "E:\workspace\venv\django_ro_venv\lib\site-packages\django\views\decorators\csrf.py", line 54, in wrapped_view
    return view_func(*args, **kwargs)
  File "E:\workspace\venv\django_ro_venv\lib\site-packages\django\views\generic\base.py", line 68, in view
    return self.dispatch(request, *args, **kwargs)
  File "E:\workspace\venv\django_ro_venv\lib\site-packages\rest_framework\views.py", line 495, in dispatch
    response = self.handle_exception(exc)
  File "E:\workspace\venv\django_ro_venv\lib\site-packages\rest_framework\views.py", line 455, in handle_exception
    self.raise_uncaught_exception(exc)
  File "E:\workspace\venv\django_ro_venv\lib\site-packages\rest_framework\views.py", line 492, in dispatch
    response = handler(request, *args, **kwargs)
  File "E:\workspace\project\django_ro\ro_operations\views.py", line 366, in delete
    print(request.DELETE)
  File "E:\workspace\venv\django_ro_venv\lib\site-packages\rest_framework\request.py", line 414, in __getattr__
    return self.__getattribute__(attr)
AttributeError: 'Request' object has no attribute 'DELETE'
2019-03-02 17:15:19,547 [Thread-2:11308] [django.request:228] [log:log_response] [ERROR]- Internal Server Error: /app_server_channels/39347/
Traceback (most recent call last):
  File "E:\workspace\venv\django_ro_venv\lib\site-packages\django\core\handlers\exception.py", line 34, in inner
    response = get_response(request)
  File "E:\workspace\venv\django_ro_venv\lib\site-packages\django\core\handlers\base.py", line 126, in _get_response
    response = self.process_exception_by_middleware(e, request)
  File "E:\workspace\venv\django_ro_venv\lib\site-packages\django\core\handlers\base.py", line 124, in _get_response
    response = wrapped_callback(request, *callback_args, **callback_kwargs)
  File "E:\workspace\venv\django_ro_venv\lib\site-packages\django\views\decorators\csrf.py", line 54, in wrapped_view
    return view_func(*args, **kwargs)
  File "E:\workspace\venv\django_ro_venv\lib\site-packages\django\views\generic\base.py", line 68, in view
    return self.dispatch(request, *args, **kwargs)
  File "E:\workspace\venv\django_ro_venv\lib\site-packages\rest_framework\views.py", line 497, in dispatch
    self.response = self.finalize_response(request, response, *args, **kwargs)
  File "E:\workspace\venv\django_ro_venv\lib\site-packages\rest_framework\views.py", line 412, in finalize_response
    % type(response)
AssertionError: Expected a `Response`, `HttpResponse` or `HttpStreamingResponse` to be returned from the view, but received a `<class 'NoneType'>`
2019-03-02 17:15:23,841 [Thread-2:11308] [django.request:228] [log:log_response] [ERROR]- Internal Server Error: /app_server_channels/39347/
Traceback (most recent call last):
  File "E:\workspace\venv\django_ro_venv\lib\site-packages\django\core\handlers\exception.py", line 34, in inner
    response = get_response(request)
  File "E:\workspace\venv\django_ro_venv\lib\site-packages\django\core\handlers\base.py", line 126, in _get_response
    response = self.process_exception_by_middleware(e, request)
  File "E:\workspace\venv\django_ro_venv\lib\site-packages\django\core\handlers\base.py", line 124, in _get_response
    response = wrapped_callback(request, *callback_args, **callback_kwargs)
  File "E:\workspace\venv\django_ro_venv\lib\site-packages\django\views\decorators\csrf.py", line 54, in wrapped_view
    return view_func(*args, **kwargs)
  File "E:\workspace\venv\django_ro_venv\lib\site-packages\django\views\generic\base.py", line 68, in view
    return self.dispatch(request, *args, **kwargs)
  File "E:\workspace\venv\django_ro_venv\lib\site-packages\rest_framework\views.py", line 497, in dispatch
    self.response = self.finalize_response(request, response, *args, **kwargs)
  File "E:\workspace\venv\django_ro_venv\lib\site-packages\rest_framework\views.py", line 412, in finalize_response
    % type(response)
AssertionError: Expected a `Response`, `HttpResponse` or `HttpStreamingResponse` to be returned from the view, but received a `<class 'NoneType'>`
2019-03-04 11:05:01,224 [Thread-3:4696] [django.request:228] [log:log_response] [WARNING]- Forbidden: /welfares/
2019-03-04 11:20:25,206 [Thread-5:6608] [django.request:228] [log:log_response] [WARNING]- Bad Request: /delete_open_plan/7631/
2019-03-04 11:22:15,561 [Thread-2:548] [django.request:228] [log:log_response] [WARNING]- Bad Request: /delete_open_plan/7631/
2019-03-04 11:22:31,838 [Thread-3:9084] [django.request:228] [log:log_response] [WARNING]- Bad Request: /delete_open_plan/7631/
2019-03-04 11:24:51,607 [Thread-2:7840] [django.request:228] [log:log_response] [WARNING]- Bad Request: /delete_open_plan/7631/
2019-03-04 11:27:23,426 [Thread-2:4440] [django.request:228] [log:log_response] [WARNING]- Bad Request: /delete_open_plan/7631/
2019-03-04 13:19:09,529 [Thread-9:14360] [django.request:228] [log:log_response] [WARNING]- Bad Request: /set_open_plan/7631/
2019-03-04 16:15:39,525 [Thread-3:13508] [django.request:228] [log:log_response] [WARNING]- Bad Request: /recommend_server_managements/
2019-03-04 16:45:40,947 [Thread-3:14716] [django.request:228] [log:log_response] [WARNING]- Bad Request: /recommend_server_managements/
2019-03-04 16:47:40,612 [Thread-2:9184] [django.request:228] [log:log_response] [WARNING]- Bad Request: /recommend_server_managements/
2019-03-04 16:56:43,828 [Thread-2:11880] [django.request:228] [log:log_response] [WARNING]- Bad Request: /recommend_server_managements/
2019-03-04 16:57:02,594 [Thread-2:11880] [django.request:228] [log:log_response] [WARNING]- Bad Request: /recommend_server_managements/
2019-03-04 16:57:12,746 [Thread-2:10440] [django.request:228] [log:log_response] [WARNING]- Bad Request: /recommend_server_managements/
2019-03-04 17:36:12,119 [Thread-2:13348] [django.request:228] [log:log_response] [ERROR]- Internal Server Error: /change_recommend/1389
Traceback (most recent call last):
  File "E:\workspace\venv\django_ro_venv\lib\site-packages\django\core\handlers\exception.py", line 34, in inner
    response = get_response(request)
  File "E:\workspace\venv\django_ro_venv\lib\site-packages\django\utils\deprecation.py", line 90, in __call__
    response = self.process_request(request)
  File "E:\workspace\venv\django_ro_venv\lib\site-packages\django\middleware\common.py", line 53, in process_request
    path = self.get_full_path_with_slash(request)
  File "E:\workspace\venv\django_ro_venv\lib\site-packages\django\middleware\common.py", line 93, in get_full_path_with_slash
    'url': request.get_host() + new_path,
RuntimeError: You called this URL via POST, but the URL doesn't end in a slash and you have APPEND_SLASH set. Django can't redirect to the slash URL while maintaining POST data. Change your form to point to 127.0.0.1:8000/change_recommend/1389/ (note the trailing slash), or set APPEND_SLASH=False in your Django settings.
